Workbook

Sheet SingleBerryFW
A1: SimulationName | B1: Clock.Today | C1: Clock.Today.Year | D1: DOY | E1: Location | F1: KiwiFruit.Fruit.SingleBerryFW | G1: KiwiFruit.Fruit.MaxSingleBerryFW | H1: KiwiFruit.Phenology.CurrentStageName | I1: KiwiFruit.Phenology.FullBloomDOY
A2: TPHW2016_2024 | B2: 44603 | C2: 2022 | D2: =B2-DATE(YEAR(B2),1,0) -> 42 | E2: Te Puke | F2: 65.7
A3: TPHW2016_2024 | B3: 44608 | C3: 2022 | D3: =B3-DATE(YEAR(B3),1,0) -> 47 | E3: Te Puke | F3: 77
A4: TPHW2016_2024 | B4: 44622 | C4: 2022 | D4: =B4-DATE(YEAR(B4),1,0) -> 61 | E4: Te Puke | F4: 108.9
A5: TPHW2016_2024 | B5: 44636 | C5: 2022 | D5: =B5-DATE(YEAR(B5),1,0) -> 75 | E5: Te Puke | F5: 87.8
A6: TPHW2016_2024 | B6: 44650 | C6: 2022 | D6: =B6-DATE(YEAR(B6),1,0) -> 89 | E6: Te Puke | F6: 92
A7: TPHW2016_2024 | B7: 44664 | C7: 2022 | D7: =B7-DATE(YEAR(B7),1,0) -> 103 | E7: Te Puke | F7: 100
A8: TPHW2016_2024 | B8: 44672 | C8: 2022 | D8: =B8-DATE(YEAR(B8),1,0) -> 111 | E8: Te Puke | F8: 102.7
A9: TPHW2016_2024 | B9: 44680 | C9: 2022 | D9: =B9-DATE(YEAR(B9),1,0) -> 119 | E9: Te Puke | F9: 102.5
A10: TPHW2016_2024 | B10: 44685 | C10: 2022 | D10: =B10-DATE(YEAR(B10),1,0) -> 124 | E10: Te Puke | F10: 105.9
A11: TPHW2016_2024 | B11: 44699 | C11: 2022 | D11: =B11-DATE(YEAR(B11),1,0) -> 138 | E11: Te Puke | F11: 110.1
A12: TPHW2016_2024 | B12: 44713 | C12: 2022 | D12: =B12-DATE(YEAR(B12),1,0) -> 152 | E12: Te Puke | F12: 108.5
A13: TPHW2016_2024 | B13: 44952 | C13: 2023 | D13: =B13-DATE(YEAR(B13),1,0) -> 26 | E13: Te Puke | F13: 67.4
... A89: TPHW2016_2024 | B89: 45453 | C89: 2024 | D89: =B89-DATE(YEAR(B89),1,0) -> 162 | E89: Te Puke | F89: 114.5
A90: TPHW2016_2024 | B90: 44595 | C90: =YEAR((B90)) -> 2022 | D90: =B90-DATE(YEAR(B90),1,0) -> 34 | E90: Te Puke | F90: 69.6
A91: TPHW2016_2024 | B91: 44608 | C91: =YEAR((B91)) -> 2022 | D91: =B91-DATE(YEAR(B91),1,0) -> 47 | E91: Te Puke | F91: 80.2
A92: TPHW2016_2024 | B92: 44622 | C92: =YEAR((B92)) -> 2022 | D92: =B92-DATE(YEAR(B92),1,0) -> 61 | E92: Te Puke | F92: 85.8
A93: TPHW2016_2024 | B93: 44636 | C93: =YEAR((B93)) -> 2022 | D93: =B93-DATE(YEAR(B93),1,0) -> 75 | E93: Te Puke | F93: 96.4
A94: TPHW2016_2024 | B94: 44650 | C94: =YEAR((B94)) -> 2022 | D94: =B94-DATE(YEAR(B94),1,0) -> 89 | E94: Te Puke | F94: 106.7
A95: TPHW2016_2024 | B95: 44664 | C95: =YEAR((B95)) -> 2022 | D95: =B95-DATE(YEAR(B95),1,0) -> 103 | E95: Te Puke | F95: 114
A96: TPHW2016_2024 | B96: 44673 | C96: =YEAR((B96)) -> 2022 | D96: =B96-DATE(YEAR(B96),1,0) -> 112 | E96: Te Puke | F96: 111.3
A97: TPHW2016_2024 | B97: 44680 | C97: =YEAR((B97)) -> 2022 | D97: =B97-DATE(YEAR(B97),1,0) -> 119 | E97: Te Puke | F97: 109.8
A98: TPHW2016_2024 | B98: 44685 | C98: =YEAR((B98)) -> 2022 | D98: =B98-DATE(YEAR(B98),1,0) -> 124 | E98: Te Puke | F98: 112.7
A99: TPHW2016_2024 | B99: 44699 | C99: =YEAR((B99)) -> 2022 | D99: =B99-DATE(YEAR(B99),1,0) -> 138 | E99: Te Puke | F99: 115.6
A100: TPHW2016_2024 | B100: 44713 | C100: =YEAR((B100)) -> 2022 | D100: =B100-DATE(YEAR(B100),1,0) -> 152 | E100: Te Puke | F100: 117.9
A101: TPHW2016_2024 | B101: 44950 | C101: =YEAR((B101)) -> 2023 | D101: =B101-DATE(YEAR(B101),1,0) -> 24 | E101: Te Puke | F101: 63.7
... A122: TPHW2016_2024 | B122: 45453 | C122: =YEAR((B122)) -> 2024 | D122: =B122-DATE(YEAR(B122),1,0) -> 162 | E122: Te Puke | F122: 99.8
A123: TPHW2016_2024 | B123: 44595 | C123: =YEAR(B123) -> 2022 | D123: =B123-DATE(YEAR(B123),1,0) -> 34 | E123: Te Puke | F123: 83.4
A124: TPHW2016_2024 | B124: 44608 | C124: =YEAR(B124) -> 2022 | D124: =B124-DATE(YEAR(B124),1,0) -> 47 | E124: Te Puke | F124: 94.3
A125: TPHW2016_2024 | B125: 44622 | C125: =YEAR(B125) -> 2022 | D125: =B125-DATE(YEAR(B125),1,0) -> 61 | E125: Te Puke | F125: 102.9
A126: TPHW2016_2024 | B126: 44636 | C126: =YEAR(B126) -> 2022 | D126: =B126-DATE(YEAR(B126),1,0) -> 75 | E126: Te Puke | F126: 104
A127: TPHW2016_2024 | B127: 44650 | C127: =YEAR(B127) -> 2022 | D127: =B127-DATE(YEAR(B127),1,0) -> 89 | E127: Te Puke | F127: 113.4
A128: TPHW2016_2024 | B128: 44664 | C128: =YEAR(B128) -> 2022 | D128: =B128-DATE(YEAR(B128),1,0) -> 103 | E128: Te Puke | F128: 125.8
A129: TPHW2016_2024 | B129: 44672 | C129: =YEAR(B129) -> 2022 | D129: =B129-DATE(YEAR(B129),1,0) -> 111 | E129: Te Puke | F129: 132.9
A130: TPHW2016_2024 | B130: 44680 | C130: =YEAR(B130) -> 2022 | D130: =B130-DATE(YEAR(B130),1,0) -> 119 | E130: Te Puke | F130: 139.8
A131: TPHW2016_2024 | B131: 44685 | C131: =YEAR(B131) -> 2022 | D131: =B131-DATE(YEAR(B131),1,0) -> 124 | E131: Te Puke | F131: 135.1
A132: TPHW2016_2024 | B132: 44699 | C132: =YEAR(B132) -> 2022 | D132: =B132-DATE(YEAR(B132),1,0) -> 138 | E132: Te Puke | F132: 138.1
A133: TPHW2016_2024 | B133: 44713 | C133: =YEAR(B133) -> 2022 | D133: =B133-DATE(YEAR(B133),1,0) -> 152 | E133: Te Puke | F133: 142
A134: TPHW2016_2024 | B134: 44952 | C134: =YEAR(B134) -> 2023 | D134: =B134-DATE(YEAR(B134),1,0) -> 26 | E134: Te Puke | F134: 61.4
... A612: KKHW2020_2024 | B612: 45454 | C612: =YEAR(B612) -> 2024 | D612: =B612-DATE(YEAR(B612),1,0) -> 163 | E612: Kerikeri | F612: 104.6
...

Sheet SingleBerryDW
A1: SimulationName | B1: Clock.Today | C1: Clock.Today.Year | D1: DOY | E1: Location | F1: KiwiFruit.Fruit.SingleBerryDW | G1: KiwiFruit.Fruit.MaxSingleBerryDW | H1: KiwiFruit.Phenology.CurrentStageName
A2: TPHW2016_2024 | B2: 44603 | C2: 2022 | D2: =B2-DATE(YEAR(B2),1,0) -> 42 | E2: Te Puke | F2: 7.4898
A3: TPHW2016_2024 | B3: 44608 | C3: 2022 | D3: =B3-DATE(YEAR(B3),1,0) -> 47 | E3: Te Puke | F3: 10.318
A4: TPHW2016_2024 | B4: 44622 | C4: 2022 | D4: =B4-DATE(YEAR(B4),1,0) -> 61 | E4: Te Puke | F4: 12.7413
A5: TPHW2016_2024 | B5: 44636 | C5: 2022 | D5: =B5-DATE(YEAR(B5),1,0) -> 75 | E5: Te Puke | F5: 10.8872
A6: TPHW2016_2024 | B6: 44650 | C6: 2022 | D6: =B6-DATE(YEAR(B6),1,0) -> 89 | E6: Te Puke | F6: 13.892
A7: TPHW2016_2024 | B7: 44664 | C7: 2022 | D7: =B7-DATE(YEAR(B7),1,0) -> 103 | E7: Te Puke | F7: 15.2
A8: TPHW2016_2024 | B8: 44672 | C8: 2022 | D8: =B8-DATE(YEAR(B8),1,0) -> 111 | E8: Te Puke | F8: 16.432
A9: TPHW2016_2024 | B9: 44680 | C9: 2022 | D9: =B9-DATE(YEAR(B9),1,0) -> 119 | E9: Te Puke | F9: 16.5025
A10: TPHW2016_2024 | B10: 44685 | C10: 2022 | D10: =B10-DATE(YEAR(B10),1,0) -> 124 | E10: Te Puke | F10: 16.7322
A11: TPHW2016_2024 | B11: 44699 | C11: 2022 | D11: =B11-DATE(YEAR(B11),1,0) -> 138 | E11: Te Puke | F11: 17.0655
A12: TPHW2016_2024 | B12: 44713 | C12: 2022 | D12: =B12-DATE(YEAR(B12),1,0) -> 152 | E12: Te Puke | F12: 17.6855
A13: TPHW2016_2024 | B13: 44952 | C13: 2023 | D13: =B13-DATE(YEAR(B13),1,0) -> 26 | E13: Te Puke | F13: 6.3356
... A89: TPHW2016_2024 | B89: 45453 | C89: 2024 | D89: =B89-DATE(YEAR(B89),1,0) -> 162 | E89: Te Puke | F89: 20.4955
A90: TPHW2016_2024 | B90: 44595 | C90: =YEAR((B90)) -> 2022 | D90: =B90-DATE(YEAR(B90),1,0) -> 34 | E90: Te Puke | F90: 6.96
A91: TPHW2016_2024 | B91: 44608 | C91: =YEAR((B91)) -> 2022 | D91: =B91-DATE(YEAR(B91),1,0) -> 47 | E91: Te Puke | F91: 9.7844
A92: TPHW2016_2024 | B92: 44622 | C92: =YEAR((B92)) -> 2022 | D92: =B92-DATE(YEAR(B92),1,0) -> 61 | E92: Te Puke | F92: 12.0978
A93: TPHW2016_2024 | B93: 44636 | C93: =YEAR((B93)) -> 2022 | D93: =B93-DATE(YEAR(B93),1,0) -> 75 | E93: Te Puke | F93: 13.3996
A94: TPHW2016_2024 | B94: 44650 | C94: =YEAR((B94)) -> 2022 | D94: =B94-DATE(YEAR(B94),1,0) -> 89 | E94: Te Puke | F94: 18.3524
A95: TPHW2016_2024 | B95: 44664 | C95: =YEAR((B95)) -> 2022 | D95: =B95-DATE(YEAR(B95),1,0) -> 103 | E95: Te Puke | F95: 17.784
A96: TPHW2016_2024 | B96: 44673 | C96: =YEAR((B96)) -> 2022 | D96: =B96-DATE(YEAR(B96),1,0) -> 112 | E96: Te Puke | F96: 17.6967
A97: TPHW2016_2024 | B97: 44680 | C97: =YEAR((B97)) -> 2022 | D97: =B97-DATE(YEAR(B97),1,0) -> 119 | E97: Te Puke | F97: 19.3248
A98: TPHW2016_2024 | B98: 44685 | C98: =YEAR((B98)) -> 2022 | D98: =B98-DATE(YEAR(B98),1,0) -> 124 | E98: Te Puke | F98: 20.5114
A99: TPHW2016_2024 | B99: 44699 | C99: =YEAR((B99)) -> 2022 | D99: =B99-DATE(YEAR(B99),1,0) -> 138 | E99: Te Puke | F99: 20.4612
A100: TPHW2016_2024 | B100: 44713 | C100: =YEAR((B100)) -> 2022 | D100: =B100-DATE(YEAR(B100),1,0) -> 152 | E100: Te Puke | F100: 21.3399
A101: TPHW2016_2024 | B101: 44950 | C101: =YEAR((B101)) -> 2023 | D101: =B101-DATE(YEAR(B101),1,0) -> 24 | E101: Te Puke | F101: 5.733
... A122: TPHW2016_2024 | B122: 45453 | C122: =YEAR((B122)) -> 2024 | D122: =B122-DATE(YEAR(B122),1,0) -> 162 | E122: Te Puke | F122: 17.964
A123: TPHW2016_2024 | B123: 44595 | C123: =YEAR(B123) -> 2022 | D123: =B123-DATE(YEAR(B123),1,0) -> 34 | E123: Te Puke | F123: 8.0898
A124: TPHW2016_2024 | B124: 44608 | C124: =YEAR(B124) -> 2022 | D124: =B124-DATE(YEAR(B124),1,0) -> 47 | E124: Te Puke | F124: 10.7502
A125: TPHW2016_2024 | B125: 44622 | C125: =YEAR(B125) -> 2022 | D125: =B125-DATE(YEAR(B125),1,0) -> 61 | E125: Te Puke | F125: 13.1712
A126: TPHW2016_2024 | B126: 44636 | C126: =YEAR(B126) -> 2022 | D126: =B126-DATE(YEAR(B126),1,0) -> 75 | E126: Te Puke | F126: 12.584
A127: TPHW2016_2024 | B127: 44650 | C127: =YEAR(B127) -> 2022 | D127: =B127-DATE(YEAR(B127),1,0) -> 89 | E127: Te Puke | F127: 16.5564
A128: TPHW2016_2024 | B128: 44664 | C128: =YEAR(B128) -> 2022 | D128: =B128-DATE(YEAR(B128),1,0) -> 103 | E128: Te Puke | F128: 18.1152
A129: TPHW2016_2024 | B129: 44672 | C129: =YEAR(B129) -> 2022 | D129: =B129-DATE(YEAR(B129),1,0) -> 111 | E129: Te Puke | F129: 19.6692
A130: TPHW2016_2024 | B130: 44680 | C130: =YEAR(B130) -> 2022 | D130: =B130-DATE(YEAR(B130),1,0) -> 119 | E130: Te Puke | F130: 20.5506
A131: TPHW2016_2024 | B131: 44685 | C131: =YEAR(B131) -> 2022 | D131: =B131-DATE(YEAR(B131),1,0) -> 124 | E131: Te Puke | F131: 19.7246
A132: TPHW2016_2024 | B132: 44699 | C132: =YEAR(B132) -> 2022 | D132: =B132-DATE(YEAR(B132),1,0) -> 138 | E132: Te Puke | F132: 21.8198
A133: TPHW2016_2024 | B133: 44713 | C133: =YEAR(B133) -> 2022 | D133: =B133-DATE(YEAR(B133),1,0) -> 152 | E133: Te Puke | F133: 22.72
A134: TPHW2016_2024 | B134: 44952 | C134: =YEAR(B134) -> 2023 | D134: =B134-DATE(YEAR(B134),1,0) -> 26 | E134: Te Puke | F134: 5.0962
... A612: KKHW2020_2024 | B612: 45454 | C612: =YEAR(B612) -> 2024 | D612: =B612-DATE(YEAR(B612),1,0) -> 163 | E612: Kerikeri | F612: 18.7234
...

Sheet SingleBerryDMC
A1: SimulationName | B1: Clock.Today | C1: Clock.Today.Year | D1: DOY | E1: Location | F1: KiwiFruit.Fruit.SingleBerryDMC | G1: KiwiFruit.Fruit.MaxSingleBerryDMC | H1: KiwiFruit.Phenology.CurrentStageName
A2: TPHW2016_2024 | B2: 44603 | C2: 2022 | D2: =B2-DATE(YEAR(B2),1,0) -> 42 | E2: Te Puke | F2: =(SingleBerryDW!F2/SingleBerryFW!F2)*100 -> 11.4
A3: TPHW2016_2024 | B3: 44608 | C3: 2022 | D3: =B3-DATE(YEAR(B3),1,0) -> 47 | E3: Te Puke | F3: =(SingleBerryDW!F3/SingleBerryFW!F3)*100 -> 13.4
A4: TPHW2016_2024 | B4: 44622 | C4: 2022 | D4: =B4-DATE(YEAR(B4),1,0) -> 61 | E4: Te Puke | F4: =(SingleBerryDW!F4/SingleBerryFW!F4)*100 -> 11.7
A5: TPHW2016_2024 | B5: 44636 | C5: 2022 | D5: =B5-DATE(YEAR(B5),1,0) -> 75 | E5: Te Puke | F5: =(SingleBerryDW!F5/SingleBerryFW!F5)*100 -> 12.4
A6: TPHW2016_2024 | B6: 44650 | C6: 2022 | D6: =B6-DATE(YEAR(B6),1,0) -> 89 | E6: Te Puke | F6: =(SingleBerryDW!F6/SingleBerryFW!F6)*100 -> 15.1
A7: TPHW2016_2024 | B7: 44664 | C7: 2022 | D7: =B7-DATE(YEAR(B7),1,0) -> 103 | E7: Te Puke | F7: =(SingleBerryDW!F7/SingleBerryFW!F7)*100 -> 15.2
A8: TPHW2016_2024 | B8: 44672 | C8: 2022 | D8: =B8-DATE(YEAR(B8),1,0) -> 111 | E8: Te Puke | F8: =(SingleBerryDW!F8/SingleBerryFW!F8)*100 -> 16
A9: TPHW2016_2024 | B9: 44680 | C9: 2022 | D9: =B9-DATE(YEAR(B9),1,0) -> 119 | E9: Te Puke | F9: =(SingleBerryDW!F9/SingleBerryFW!F9)*100 -> 16.1
A10: TPHW2016_2024 | B10: 44685 | C10: 2022 | D10: =B10-DATE(YEAR(B10),1,0) -> 124 | E10: Te Puke | F10: =(SingleBerryDW!F10/SingleBerryFW!F10)*100 -> 15.8
A11: TPHW2016_2024 | B11: 44699 | C11: 2022 | D11: =B11-DATE(YEAR(B11),1,0) -> 138 | E11: Te Puke | F11: =(SingleBerryDW!F11/SingleBerryFW!F11)*100 -> 15.5
A12: TPHW2016_2024 | B12: 44713 | C12: 2022 | D12: =B12-DATE(YEAR(B12),1,0) -> 152 | E12: Te Puke | F12: =(SingleBerryDW!F12/SingleBerryFW!F12)*100 -> 16.3
A13: TPHW2016_2024 | B13: 44952 | C13: 2023 | D13: =B13-DATE(YEAR(B13),1,0) -> 26 | E13: Te Puke | F13: =(SingleBerryDW!F13/SingleBerryFW!F13)*100 -> 9.4
... A89: TPHW2016_2024 | B89: 45453 | C89: 2024 | D89: =B89-DATE(YEAR(B89),1,0) -> 162 | E89: Te Puke | F89: =(SingleBerryDW!F89/SingleBerryFW!F89)*100 -> 17.9
A90: TPHW2016_2024 | B90: 44595 | C90: =YEAR((B90)) -> 2022 | D90: =B90-DATE(YEAR(B90),1,0) -> 34 | E90: Te Puke | F90: =(SingleBerryDW!F90/SingleBerryFW!F90)*100 -> 10
A91: TPHW2016_2024 | B91: 44608 | C91: =YEAR((B91)) -> 2022 | D91: =B91-DATE(YEAR(B91),1,0) -> 47 | E91: Te Puke | F91: =(SingleBerryDW!F91/SingleBerryFW!F91)*100 -> 12.2
A92: TPHW2016_2024 | B92: 44622 | C92: =YEAR((B92)) -> 2022 | D92: =B92-DATE(YEAR(B92),1,0) -> 61 | E92: Te Puke | F92: =(SingleBerryDW!F92/SingleBerryFW!F92)*100 -> 14.1
A93: TPHW2016_2024 | B93: 44636 | C93: =YEAR((B93)) -> 2022 | D93: =B93-DATE(YEAR(B93),1,0) -> 75 | E93: Te Puke | F93: =(SingleBerryDW!F93/SingleBerryFW!F93)*100 -> 13.9
A94: TPHW2016_2024 | B94: 44650 | C94: =YEAR((B94)) -> 2022 | D94: =B94-DATE(YEAR(B94),1,0) -> 89 | E94: Te Puke | F94: =(SingleBerryDW!F94/SingleBerryFW!F94)*100 -> 17.2
A95: TPHW2016_2024 | B95: 44664 | C95: =YEAR((B95)) -> 2022 | D95: =B95-DATE(YEAR(B95),1,0) -> 103 | E95: Te Puke | F95: =(SingleBerryDW!F95/SingleBerryFW!F95)*100 -> 15.6
A96: TPHW2016_2024 | B96: 44673 | C96: =YEAR((B96)) -> 2022 | D96: =B96-DATE(YEAR(B96),1,0) -> 112 | E96: Te Puke | F96: =(SingleBerryDW!F96/SingleBerryFW!F96)*100 -> 15.9
A97: TPHW2016_2024 | B97: 44680 | C97: =YEAR((B97)) -> 2022 | D97: =B97-DATE(YEAR(B97),1,0) -> 119 | E97: Te Puke | F97: =(SingleBerryDW!F97/SingleBerryFW!F97)*100 -> 17.6
A98: TPHW2016_2024 | B98: 44685 | C98: =YEAR((B98)) -> 2022 | D98: =B98-DATE(YEAR(B98),1,0) -> 124 | E98: Te Puke | F98: =(SingleBerryDW!F98/SingleBerryFW!F98)*100 -> 18.2
A99: TPHW2016_2024 | B99: 44699 | C99: =YEAR((B99)) -> 2022 | D99: =B99-DATE(YEAR(B99),1,0) -> 138 | E99: Te Puke | F99: =(SingleBerryDW!F99/SingleBerryFW!F99)*100 -> 17.7
A100: TPHW2016_2024 | B100: 44713 | C100: =YEAR((B100)) -> 2022 | D100: =B100-DATE(YEAR(B100),1,0) -> 152 | E100: Te Puke | F100: =(SingleBerryDW!F100/SingleBerryFW!F100)*100 -> 18.1
A101: TPHW2016_2024 | B101: 44950 | C101: =YEAR((B101)) -> 2023 | D101: =B101-DATE(YEAR(B101),1,0) -> 24 | E101: Te Puke | F101: =(SingleBerryDW!F101/SingleBerryFW!F101)*100 -> 9
... A122: TPHW2016_2024 | B122: 45453 | C122: =YEAR((B122)) -> 2024 | D122: =B122-DATE(YEAR(B122),1,0) -> 162 | E122: Te Puke | F122: =(SingleBerryDW!F122/SingleBerryFW!F122)*100 -> 18
A123: TPHW2016_2024 | B123: 44595 | C123: =YEAR(B123) -> 2022 | D123: =B123-DATE(YEAR(B123),1,0) -> 34 | E123: Te Puke | F123: =(SingleBerryDW!F123/SingleBerryFW!F123)*100 -> 9.7
A124: TPHW2016_2024 | B124: 44608 | C124: =YEAR(B124) -> 2022 | D124: =B124-DATE(YEAR(B124),1,0) -> 47 | E124: Te Puke | F124: =(SingleBerryDW!F124/SingleBerryFW!F124)*100 -> 11.4
A125: TPHW2016_2024 | B125: 44622 | C125: =YEAR(B125) -> 2022 | D125: =B125-DATE(YEAR(B125),1,0) -> 61 | E125: Te Puke | F125: =(SingleBerryDW!F125/SingleBerryFW!F125)*100 -> 12.8
A126: TPHW2016_2024 | B126: 44636 | C126: =YEAR(B126) -> 2022 | D126: =B126-DATE(YEAR(B126),1,0) -> 75 | E126: Te Puke | F126: =(SingleBerryDW!F126/SingleBerryFW!F126)*100 -> 12.1
A127: TPHW2016_2024 | B127: 44650 | C127: =YEAR(B127) -> 2022 | D127: =B127-DATE(YEAR(B127),1,0) -> 89 | E127: Te Puke | F127: =(SingleBerryDW!F127/SingleBerryFW!F127)*100 -> 14.6
A128: TPHW2016_2024 | B128: 44664 | C128: =YEAR(B128) -> 2022 | D128: =B128-DATE(YEAR(B128),1,0) -> 103 | E128: Te Puke | F128: =(SingleBerryDW!F128/SingleBerryFW!F128)*100 -> 14.4
A129: TPHW2016_2024 | B129: 44672 | C129: =YEAR(B129) -> 2022 | D129: =B129-DATE(YEAR(B129),1,0) -> 111 | E129: Te Puke | F129: =(SingleBerryDW!F129/SingleBerryFW!F129)*100 -> 14.8
A130: TPHW2016_2024 | B130: 44680 | C130: =YEAR(B130) -> 2022 | D130: =B130-DATE(YEAR(B130),1,0) -> 119 | E130: Te Puke | F130: =(SingleBerryDW!F130/SingleBerryFW!F130)*100 -> 14.7
A131: TPHW2016_2024 | B131: 44685 | C131: =YEAR(B131) -> 2022 | D131: =B131-DATE(YEAR(B131),1,0) -> 124 | E131: Te Puke | F131: =(SingleBerryDW!F131/SingleBerryFW!F131)*100 -> 14.6
A132: TPHW2016_2024 | B132: 44699 | C132: =YEAR(B132) -> 2022 | D132: =B132-DATE(YEAR(B132),1,0) -> 138 | E132: Te Puke | F132: =(SingleBerryDW!F132/SingleBerryFW!F132)*100 -> 15.8
A133: TPHW2016_2024 | B133: 44713 | C133: =YEAR(B133) -> 2022 | D133: =B133-DATE(YEAR(B133),1,0) -> 152 | E133: Te Puke | F133: =(SingleBerryDW!F133/SingleBerryFW!F133)*100 -> 16
A134: TPHW2016_2024 | B134: 44952 | C134: =YEAR(B134) -> 2023 | D134: =B134-DATE(YEAR(B134),1,0) -> 26 | E134: Te Puke | F134: =(SingleBerryDW!F134/SingleBerryFW!F134)*100 -> 8.3
... A612: KKHW2020_2024 | B612: 45454 | C612: =YEAR(B612) -> 2024 | D612: =B612-DATE(YEAR(B612),1,0) -> 163 | E612: Kerikeri | F612: =(SingleBerryDW!F612/SingleBerryFW!F612)*100 -> 17.9
...

Sheet FullBloom
A1: SimulationName | B1: Clock.Today | C1: Clock.Today.Year | D1: DOY | E1: Location | F1: KiwiFruit.Fruit.SingleBerryFW | G1: KiwiFruit.Fruit.MaxSingleBerryFW | H1: KiwiFruit.Phenology.CurrentStageName | I1: KiwiFruit.Phenology.FullBloomDOY | J1: Clock.Today.Year
A2: TPHW2016 | B2: 42387 | C2: 2016 | E2: Te Puke | F2: 59.6 | G2: =F2 -> 59.6 | I2: 332 | J2: =YEAR(B2) -> 2016 | M2: 42330
A3: TPHW2016 | B3: 42387 | C3: 2016 | E3: Te Puke | F3: 58.3 | G3: =F3 -> 58.3 | I3: 332 | J3: =YEAR(B3) -> 2016 | M3: 42337
A4: TPHW2016 | B4: 42423 | C4: 2016 | E4: Te Puke | F4: 74.4 | G4: =F4 -> 74.4 | I4: 332 | J4: =YEAR(B4) -> 2016 | M4: 42334
A5: TPHW2016 | B5: 42423 | C5: 2016 | E5: Te Puke | F5: 85.7 | G5: =F5 -> 85.7 | I5: 332 | J5: =YEAR(B5) -> 2016 | M5: 42336
A6: TPHW2016 | B6: 42437 | C6: 2016 | E6: Te Puke | F6: 79.4 | G6: =F6 -> 79.4 | I6: 332 | J6: =YEAR(B6) -> 2016 | M6: 42334
A7: TPHW2016 | B7: 42437 | C7: 2016 | E7: Te Puke | F7: 92.4 | G7: =F7 -> 92.4 | I7: 332 | J7: =YEAR(B7) -> 2016 | M7: 42339
A8: TPHW2016 | B8: 42451 | C8: 2016 | E8: Te Puke | F8: 91.9 | G8: =F8 -> 91.9 | I8: 332 | J8: =YEAR(B8) -> 2016 | M8: 42333
A9: TPHW2016 | B9: 42451 | C9: 2016 | E9: Te Puke | F9: 101.1 | G9: =F9 -> 101.1 | I9: 332 | J9: =YEAR(B9) -> 2016 | M9: 42334
A10: TPHW2016 | B10: 42466 | C10: 2016 | E10: Te Puke | F10: 94.9 | G10: =F10 -> 94.9 | I10: 332 | J10: =YEAR(B10) -> 2016 | M10: 42339
A11: TPHW2016 | B11: 42467 | C11: 2016 | E11: Te Puke | F11: 113.4 | G11: =F11 -> 113.4 | I11: 332 | J11: =YEAR(B11) -> 2016 | M11: 42330
A12: TPHW2016 | B12: 42474 | C12: 2016 | E12: Te Puke | F12: 115.3 | G12: =F12 -> 115.3 | I12: 332 | J12: =YEAR(B12) -> 2016 | M12: 42337
A13: TPHW2016 | B13: 42475 | C13: 2016 | E13: Te Puke | F13: 101.2 | G13: =F13 -> 101.2 | I13: 332 | J13: =YEAR(B13) -> 2016 | M13: 42334
... A24: TPHW2016 | B24: 42535 | C24: 2016 | E24: Te Puke | F24: 106.7 | G24: =F24 -> 106.7 | I24: 332 | J24: =YEAR(B24) -> 2016 | M24: 42339
A25: TPHW2016 | B25: 42535 | C25: 2016 | E25: Te Puke | F25: 118.4 | G25: =F25 -> 118.4 | H25: EndFlowering | I25: 332 | J25: =YEAR(B25) -> 2016 | M25: 42330
A26: TPHW2016 | B26: 42386 | C26: 2016 | E26: Te Puke | F26: 56.9 | G26: =F26 -> 56.9 | I26: 332 | J26: =YEAR(B26) -> 2016 | M26: 42337
A27: TPHW2016 | B27: 42424 | C27: 2016 | E27: Te Puke | F27: 81.2 | G27: =F27 -> 81.2 | I27: 332 | J27: =YEAR(B27) -> 2016 | M27: 42334
A28: TPHW2016 | B28: 42439 | C28: 2016 | E28: Te Puke | F28: 94.7 | G28: =F28 -> 94.7 | I28: 332 | J28: =YEAR(B28) -> 2016 | M28: 42336
A29: TPHW2016 | B29: 42452 | C29: 2016 | E29: Te Puke | F29: 97.8 | G29: =F29 -> 97.8 | I29: 332 | J29: =YEAR(B29) -> 2016 | M29: 42333
A30: TPHW2016 | B30: 42467 | C30: 2016 | E30: Te Puke | F30: 109.2 | G30: =F30 -> 109.2 | I30: 332 | J30: =YEAR(B30) -> 2016 | M30: 42334
A31: TPHW2016 | B31: 42474 | C31: 2016 | E31: Te Puke | F31: 107.3 | G31: =F31 -> 107.3 | I31: 332 | J31: =YEAR(B31) -> 2016 | M31: 42330
A32: TPHW2016 | B32: 42482 | C32: 2016 | E32: Te Puke | F32: 112.8 | G32: =F32 -> 112.8 | I32: 332 | J32: =YEAR(B32) -> 2016 | M32: 42337
A33: TPHW2016 | B33: 42489 | C33: 2016 | E33: Te Puke | F33: 110.8 | G33: =F33 -> 110.8 | I33: 332 | J33: =YEAR(B33) -> 2016 | M33: 42339
A34: TPHW2016 | B34: 42496 | C34: 2016 | E34: Te Puke | F34: 115.6 | G34: =F34 -> 115.6 | I34: 332 | J34: =YEAR(B34) -> 2016 | M34: 42334
A35: TPHW2016 | B35: 42510 | C35: 2016 | E35: Te Puke | F35: 114.4 | G35: =F35 -> 114.4 | I35: 332 | J35: =YEAR(B35) -> 2016 | M35: 42336
A36: TPHW2016 | B36: 42523 | C36: 2016 | E36: Te Puke | F36: 113.8 | G36: =F36 -> 113.8 | I36: 332 | J36: =YEAR(B36) -> 2016 | M36: 42333
A37: TPHW2016 | B37: 42535 | C37: 2016 | E37: Te Puke | F37: 119.1 | G37: =F37 -> 119.1 | H37: EndFlowering | I37: 332 | J37: =YEAR(B37) -> 2016 | M37: 42339
A38: TPHW2016 | B38: 42386 | C38: 2016 | E38: Te Puke | F38: 65.2 | G38: =F38 -> 65.2 | I38: 332 | J38: =YEAR(B38) -> 2016 | M38: 42336
A39: TPHW2016 | B39: 42386 | C39: 2016 | E39: Te Puke | F39: 62.3 | G39: =F39 -> 62.3 | I39: 332 | J39: =YEAR(B39) -> 2016 | M39: 42333
A40: TPHW2016 | B40: 42386 | C40: 2016 | E40: Te Puke | F40: 61.2 | G40: =F40 -> 61.2 | I40: 332 | J40: =YEAR(B40) -> 2016 | M40: 42334
A41: TPHW2016 | B41: 42389 | C41: 2016 | E41: Te Puke | F41: 61 | G41: =F41 -> 61 | I41: 332 | J41: =YEAR(B41) -> 2016 | M41: 42330
A42: TPHW2016 | B42: 42424 | C42: 2016 | E42: Te Puke | F42: 91.7 | G42: =F42 -> 91.7 | I42: 332 | J42: =YEAR(B42) -> 2016 | M42: 42337
A43: TPHW2016 | B43: 42424 | C43: 2016 | E43: Te Puke | F43: 88.5 | G43: =F43 -> 88.5 | I43: 332 | J43: =YEAR(B43) -> 2016 | M43: 42334
A44: TPHW2016 | B44: 42424 | C44: 2016 | E44: Te Puke | F44: 81.3 | G44: =F44 -> 81.3 | I44: 332 | J44: =YEAR(B44) -> 2016 | M44: 42334
A45: TPHW2016 | B45: 42424 | C45: 2016 | E45: Te Puke | F45: 78.6 | G45: =F45 -> 78.6 | I45: 332 | J45: =YEAR(B45) -> 2016 | M45: 42330
A46: TPHW2016 | B46: 42438 | C46: 2016 | E46: Te Puke | F46: 85.2 | G46: =F46 -> 85.2 | I46: 332 | J46: =YEAR(B46) -> 2016 | M46: 42337
A47: TPHW2016 | B47: 42439 | C47: 2016 | E47: Te Puke | F47: 100.6 | G47: =F47 -> 100.6 | I47: 332 | J47: =YEAR(B47) -> 2016 | M47: 42339
A48: TPHW2016 | B48: 42439 | C48: 2016 | E48: Te Puke | F48: 99.5 | G48: =F48 -> 99.5 | I48: 332 | J48: =YEAR(B48) -> 2016 | M48: 42334
A49: TPHW2016 | B49: 42439 | C49: 2016 | E49: Te Puke | F49: 85.7 | G49: =F49 -> 85.7 | I49: 332 | J49: =YEAR(B49) -> 2016 | M49: 42336
... A83: TPHW2016 | B83: 42535 | C83: 2016 | E83: Te Puke | F83: 123.9 | G83: =F83 -> 123.9 | I83: 332 | J83: =YEAR(B83) -> 2016 | M83: 42334
...

Sheet Calculations
A1: SimulationName | B1: Maturity date | C1: Maturity DOY | D1: MatureFW | E1: MatureDW | F1: MatureDMC
A2: TPHW2016 | B2: 42491 | C2: =B2-DATE(YEAR(B2),1,0) -> 122 | D2: =27.417*LN(C2)-21.056 -> 110.65584 | E2: =7.5203*LN(C2) - 18.204 -> 17.923679 | F2: =4.5311*LN(C2) - 5.5574 -> 16.2101
A3: TPHW2017 | B3: 42856 | C3: =B3-DATE(YEAR(B3),1,0) -> 121 | D3: =29.81*LN(C3)-23.18 -> 119.78252 | E3: =8.0727*LN(C3) - 18.996 -> 19.718978 | F3: =4.2989*LN(C3) - 4.1826 -> 16.434024
A4: TPHW2018 | B4: 43221 | C4: =B4-DATE(YEAR(B4),1,0) -> 121 | D4: =24.59*LN(C4)-8.78 -> 109.14849 | E4: =7.3045*LN(C4) - 16.868 -> 18.162852 | F4: =4.717*LN(C4) - 5.8565 -> 16.765244
A5: TPHW2019 | B5: 43586 | C5: =B5-DATE(YEAR(B5),1,0) -> 121 | D5: =22.45*LN(C5)-4.7 -> 102.9655 | E5: =6.5159*LN(C5) - 13.701 -> 17.547892 | F5: =4.4925*LN(C5) - 4.2394 -> 17.305689
A6: TPHW2020 | B6: 43952 | C6: =B6-DATE(YEAR(B6),1,0) -> 122 | D6: =23.529*LN(C6) - 7.8187 -> 105.21511 | E6: =7.8195*LN(C6) - 18.793 -> 18.772043 | F6: =5.2134*LN(C6) - 7.0613 -> 17.983983
A7: TPHW2021 | B7: 44317 | C7: =B7-DATE(YEAR(B7),1,0) -> 121 | D7: =28.894*LN(C7) - 33.413 -> 105.15657 | E7: =8.7529*LN(C7) - 23.525 -> 18.452075 | F7: =5.2782*LN(C7) - 7.6739 -> 17.639242
A8: TPHW2022 | B8: 44682 | C8: =B8-DATE(YEAR(B8),1,0) -> 121 | D8: =35.269*LN(C8) - 48.839 -> 120.30374 | E8: =9.8786*LN(C8) - 27.385 -> 19.990696 | F8: =4.7126*LN(C8) - 5.9565 -> 16.644143
A9: TPHW2023 | B9: 45047 | C9: =B9-DATE(YEAR(B9),1,0) -> 121 | D9: =33.147*LN(C9) - 43.652 -> 115.31407 | E9: =9.2757*LN(C9) - 24.904 -> 19.580314 | F9: =4.7697*LN(C9) - 5.9803 -> 16.894182
A10: TPHW2024 | B10: 45413 | C10: =B10-DATE(YEAR(B10),1,0) -> 122 | D10: =23.659*LN(C10) - 15.267 -> 98.391334 | E10: =7.2391*LN(C10) - 18.129 -> 16.647789 | F10: =4.803*LN(C10) - 6.1369 -> 16.936813
A11: KKHW2020 | B11: 43952 | C11: =B11-DATE(YEAR(B11),1,0) -> 122 | D11: =29.249*LN(C11) - 29.474 -> 111.03881 | E11: =7.0115*LN(C11) - 14.752 -> 18.931394 | F11: =3.2847*LN(C11) + 1.4713 -> 17.251068
A12: KKHW2021 | B12: 44317 | C12: =B12-DATE(YEAR(B12),1,0) -> 121 | D12: =28.918*LN(C12) - 30.791 -> 107.89367 | E12: =7.6256*LN(C12) - 18.693 -> 17.87778 | F12: =3.9123*LN(C12) - 2.1343 -> 16.628271
A13: KKHW2022 | B13: 44682 | C13: =B13-DATE(YEAR(B13),1,0) -> 121 | D13: =37.134*LN(C13) - 67.128 -> 110.95889 | E13: =10.575*LN(C13) - 31.244 -> 19.471485 | F13: =5.4035*LN(C13) - 8.3163 -> 17.597754
A14: KKHW2023 | B14: 45047 | C14: =B14-DATE(YEAR(B14),1,0) -> 121 | D14: =31.85*LN(C14) - 28.15 -> 124.59593 | E14: =10.179*LN(C14) - 25.831 -> 22.985352 | F14: =5.2677*LN(C14) - 6.7698 -> 18.492986
A15: KKHW2024 | B15: 45413 | C15: =B15-DATE(YEAR(B15),1,0) -> 122 | D15: =19.88*LN(C15) + 6.1182 -> 101.62214 | E15: =6.5366*LN(C15) - 13.658 -> 17.743964 | F15: =4.2061*LN(C15) - 2.6869 -> 17.519293
A16: AKLDHW2020 | B16: 43952 | C16: =B16-DATE(YEAR(B16),1,0) -> 122 | D16: =27.791*LN(C16) - 21.427 -> 112.08155 | E16: =8.6223*LN(C16) - 21.009 -> 20.412711 | F16: =4.815*LN(C16) - 4.8836 -> 18.247761
A17: AKLDHW2021 | B17: 44317 | C17: =B17-DATE(YEAR(B17),1,0) -> 121 | D17: =24.472*LN(C17) - 10.113 -> 107.24959 | E17: =8.1134*LN(C17) - 18.723 -> 20.187167 | F17: =4.6819*LN(C17) - 3.5369 -> 18.916512
A18: AKLDHW2022 | B18: 44682 | C18: =B18-DATE(YEAR(B18),1,0) -> 121 | D18: =32.51*LN(C18) - 42.554 -> 113.35715 | E18: =10.27*LN(C18) - 27.358 -> 21.894769 | F18: =5.129*LN(C18) - 5.2481 -> 19.34951
A19: AKLDHW2023 | B19: 45047 | C19: =B19-DATE(YEAR(B19),1,0) -> 121 | D19: =28.494*LN(C19) - 20.737 -> 115.91426 | E19: =8.0217*LN(C19) - 18.98 -> 19.490393 | F19: =4.0582*LN(C19) - 2.5446 -> 16.917677
A20: AKLDHW2024 | B20: 45413 | C20: =B20-DATE(YEAR(B20),1,0) -> 122 | D20: =25.329*LN(C20) - 18.082 -> 103.59905 | E20: =7.4099*LN(C20) - 18.019 -> 17.578316 | F20: =4.544*LN(C20) - 4.75 -> 17.079472
